Workbook

Sheet Criterios
A1: ID | B1: Táxon | C1: RN | D1: Dispositivo | E1: Bloco | F1: Classificação | G1: Finalidade | H1: Restrição de subgrupo | I1: Escopo operacional CIUCA | J1: Condição / exceção explícita | K1: Redação literal | L1: Nota / divergência
A2: R57-001 | B2: Roedores e lagomorfos | C2: RN 57/2022 | D2: art. 2º, I, "a" | E2: Infraestrutura | F2: Obrigatório | G2: criação | I2: criação | K2: instalações de criação de animais separadas dos biotérios com outras finalidades
A3: R57-002 | B3: Roedores e lagomorfos | C3: RN 57/2022 | D3: art. 2º, I, "b" | E3: Infraestrutura | F3: Obrigatório | G3: criação | I3: criação | J3: em caso de edificação que abrigue biotérios com diferentes finalidades | K3: instalações de criação de animais com áreas físicas e rotinas com barreiras exclusivas, delimitadas e separadas dos biotérios de manutenção e de utilização, em caso de edificação que abrigue biotérios com diferentes finalidades
A4: R57-003 | B4: Roedores e lagomorfos | C4: RN 57/2022 | D4: art. 2º, I, "c" | E4: Infraestrutura | F4: Obrigatório | G4: criação | I4: criação | K4: área destinadas à recepção e quarentena, em biotérios de criação, para ingresso de animais
A5: R57-004 | B5: Roedores e lagomorfos | C5: RN 57/2022 | D5: art. 2º, I, "d" | E5: Infraestrutura | F5: Obrigatório | G5: todas | I5: criação; manutenção; utilização | K5: áreas destinadas à higienização (lavagem, desinfecção ou esterilização de materiais) fisicamente separadas das salas de animais
A6: R57-005 | B6: Roedores e lagomorfos | C6: RN 57/2022 | D6: art. 2º, I, "e" | E6: Infraestrutura | F6: Obrigatório | G6: criação | I6: criação | K6: sanitários localizados fora de áreas controladas, em biotérios de criação
A7: R57-006 | B7: Roedores e lagomorfos | C7: RN 57/2022 | D7: art. 2º, I, "f" | E7: Infraestrutura | F7: Obrigatório | G7: todas | I7: criação; manutenção; utilização | K7: salas de animais separadas por espécie
A8: R57-007 | B8: Roedores e lagomorfos | C8: RN 57/2022 | D8: art. 2º, I, "g" | E8: Infraestrutura | F8: Obrigatório | G8: todas | I8: criação; manutenção; utilização | K8: vestiários
A9: R57-008 | B9: Roedores e lagomorfos | C9: RN 57/2022 | D9: art. 2º, I, "h" | E9: Infraestrutura | F9: Obrigatório | G9: criação; manutenção | I9: criação; manutenção | K9: sala destinada a eutanásia, separada das salas de animais, em biotérios de criação e manutenção
A10: R57-009 | B10: Roedores e lagomorfos | C10: RN 57/2022 | D10: art. 2º, I, "i" | E10: Infraestrutura | F10: Obrigatório | G10: todas | I10: criação; manutenção; utilização | K10: local para estocagem de alimentos e forração, que atenda às recomendações dos fabricantes e que mantenha os materiais sem contato com o piso ou paredes
A11: R57-010 | B11: Roedores e lagomorfos | C11: RN 57/2022 | D11: art. 2º, I, "j" | E11: Infraestrutura | F11: Obrigatório | G11: todas | I11: criação; manutenção; utilização | K11: área exclusiva para depósitos de resíduos
A12: R57-011 | B12: Roedores e lagomorfos | C12: RN 57/2022 | D12: art. 2º, I, "k" | E12: Infraestrutura | F12: Obrigatório | G12: todas | I12: criação; manutenção; utilização | K12: freezer para acondicionar carcaças de animais
A13: R57-012 | B13: Roedores e lagomorfos | C13: RN 57/2022 | D13: art. 2º, I, "l" | E13: Infraestrutura | F13: Obrigatório | G13: todas | I13: criação; manutenção; utilização | K13: paredes, pisos e tetos lisos, livres de rejuntes e reentrâncias, e construídos com materiais que possibilitem higienização e desinfecção
A14: R57-013 | B14: Roedores e lagomorfos | C14: RN 57/2022 | D14: art. 2º, I, "m" | E14: Infraestrutura | F14: Obrigatório | G14: todas | I14: criação; manutenção; utilização | K14: ausência de janelas com acesso direto para as salas de animais de laboratório
A15: R57-014 | B15: Roedores e lagomorfos | C15: RN 57/2022 | D15: art. 2º, I, "n" | E15: Infraestrutura | F15: Obrigatório | G15: todas | I15: criação; manutenção; utilização | J15: na ausência de grupo gerador próprio | K15: sistema de monitoramento remoto da ambiência das salas dos animais, na ausência de grupo gerador próprio
A16: R57-015 | B16: Roedores e lagomorfos | C16: RN 57/2022 | D16: art. 2º, I, "o" | E16: Infraestrutura | F16: Obrigatório | G16: todas | I16: criação; manutenção; utilização | K16: sistema de iluminação com fotoperíodo regulável nas áreas controladas e salas de animais
A17: R57-016 | B17: Roedores e lagomorfos | C17: RN 57/2022 | D17: art. 2º, I, "p" | E17: Infraestrutura | F17: Obrigatório | G17: todas | I17: criação; manutenção; utilização | K17: salas de animais com ventilação, exaustão temperatura e umidade, controladas conforme as características das espécies mantidas no recinto
A18: R57-017 | B18: Roedores e lagomorfos | C18: RN 57/2022 | D18: art. 2º, I, "q" | E18: Infraestrutura | F18: Obrigatório | G18: todas | I18: criação; manutenção; utilização | K18: barreiras sanitárias de bioexclusão e biocontenção preconizadas pelo nível de biossegurança da instalação
A19: R57-018 | B19: Roedores e lagomorfos | C19: RN 57/2022 | D19: art. 2º, II, "a" | E19: Procedimentos | F19: Obrigatório | G19: manutenção; experimentação | I19: manutenção; utilização | J19: exceto animais com estado sanitário conhecido e compatível com o biotério de destino | K19: ingresso de animais, em biotérios de manutenção e experimentação, por meio de recepção em área de quarentena, exceto com relação aos animais com estado sanitário conhecido e compatível com o biotério de destino, que poderão ser introduzidos diretamente na sala de animais
A20: R57-019 | B20: Roedores e lagomorfos | C20: RN 57/2022 | D20: art. 2º, II, "b" | E20: Procedimentos | F20: Obrigatório | G20: todas | I20: criação; manutenção; utilização | K20: monitoramento com registro das condições ambientais das salas de animais
A21: R57-020 | B21: Roedores e lagomorfos | C21: RN 57/2022 | D21: art. 2º, II, "c" | E21: Procedimentos | F21: Obrigatório | G21: todas | I21: criação; manutenção; utilização | K21: uso de equipamentos de proteção individual preconizados pelo nível de biossegurança da instalação
A22: R57-021 | B22: Roedores e lagomorfos | C22: RN 57/2022 | D22: art. 2º, II, "d" | E22: Procedimentos | F22: Obrigatório | G22: criação | I22: criação | K22: disponibilização de Manual de Procedimentos Operacionais Padrão (POPs) em biotérios de criação
A23: R57-022 | B23: Roedores e lagomorfos | C23: RN 57/2022 | D23: art. 2º, II, "e" | E23: Procedimentos | F23: Obrigatório | G23: todas | I23: criação; manutenção; utilização | J23: exceto casos autorizados pela CEUA ou recomendações clínicas | K23: alojamento de animais em pares ou grupos, exceto em casos autorizados pela CEUA ou em virtude de recomendações clínicas
A24: R57-023 | B24: Roedores e lagomorfos | C24: RN 57/2022 | D24: art. 2º, II, "f" | E24: Procedimentos | F24: Obrigatório | G24: todas | I24: criação; manutenção; utilização | K24: realização de procedimentos experimentais em local diferente das salas de manutenção e criação de animais
A25: R57-024 | B25: Roedores e lagomorfos | C25: RN 57/2022 | D25: art. 2º, II, "g" | E25: Procedimentos | F25: Obrigatório | G25: todas | I25: criação; manutenção; utilização | K25: adoção de práticas de enriquecimento ambiental
A26: R57-025 | B26: Roedores e lagomorfos | C26: RN 57/2022 | D26: art. 3º, I | E26: Infraestrutura | F26: Recomendado | G26: todas | I26: criação; manutenção; utilização | K26: área administrativa
A27: R57-026 | B27: Roedores e lagomorfos | C27: RN 57/2022 | D27: art. 3º, II | E27: Infraestrutura | F27: Recomendado | G27: todas | I27: criação; manutenção; utilização | K27: área de recepção de pessoal (usuários e visitantes)
A28: R57-027 | B28: Roedores e lagomorfos | C28: RN 57/2022 | D28: art. 3º, III | E28: Infraestrutura | F28: Recomendado | G28: experimentação | I28: utilização | K28: sala destinada a eutanásia, separada das salas de procedimentos, em biotérios de experimentação
A29: R57-028 | B29: Roedores e lagomorfos | C29: RN 57/2022 | D29: art. 3º, IV | E29: Infraestrutura | F29: Recomendado | G29: todas | I29: criação; manutenção; utilização | K29: local para armazenamento de produtos químicos e medicamentos
A30: R57-029 | B30: Roedores e lagomorfos | C30: RN 57/2022 | D30: art. 3º, V | E30: Infraestrutura | F30: Recomendado | G30: todas | I30: criação; manutenção; utilização | K30: grupo gerador próprio para fornecimento emergencial de energia elétrica
A31: R57-030 | B31: Roedores e lagomorfos | C31: RN 57/2022 | D31: art. 3º, parágrafo único | E31: Procedimentos | F31: Recomendado | G31: todas | I31: criação; manutenção; utilização | K31: é recomendada a realização de controle genético e sanitário
A32: R59-031 | B32: Cães e gatos | C32: RN 59/2023 | D32: art. 2º, I, "a" | E32: Infraestrutura | F32: Obrigatório | G32: criação | I32: criação | K32: instalações de criação de animais separadas das instalações com outras finalidades
A33: R59-032 | B33: Cães e gatos | C33: RN 59/2023 | D33: art. 2º, I, "b" | E33: Infraestrutura | F33: Obrigatório | G33: criação | I33: criação | J33: em caso de edificação que abrigue biotérios com diferentes finalidades | K33: instalações de criação de animais com áreas físicas e rotinas com barreiras exclusivas, delimitadas e separadas das instalações de manutenção e de utilização, em caso de edificação que abrigue biotérios com diferentes finalidades
A34: R59-033 | B34: Cães e gatos | C34: RN 59/2023 | D34: art. 2º, I, "c" | E34: Infraestrutura | F34: Obrigatório | G34: todas | I34: criação; manutenção; utilização | K34: áreas de alojamento de cães e gatos isoladas acústica e visualmente uma da outra
A35: R59-034 | B35: Cães e gatos | C35: RN 59/2023 | D35: art. 2º, I, "d" | E35: Infraestrutura | F35: Obrigatório | G35: todas | I35: criação; manutenção; utilização | K35: ambientes específicos apropriados para os procedimentos experimentais executados na instalação
A36: R59-035 | B36: Cães e gatos | C36: RN 59/2023 | D36: art. 2º, I, "e" | E36: Infraestrutura | F36: Obrigatório | G36: todas | I36: criação; manutenção; utilização | K36: áreas de higienização separadas das salas de animais
A37: R59-036 | B37: Cães e gatos | C37: RN 59/2023 | D37: art. 2º, I, "f" | E37: Infraestrutura | F37: Obrigatório | G37: todas | I37: criação; manutenção; utilização | K37: sanitários separados das áreas controladas ou de criação | L37: DIVERGÊNCIA: o Anexo restringe às instalações de criação. Prevalece o artigo.
A38: R59-037 | B38: Cães e gatos | C38: RN 59/2023 | D38: art. 2º, I, "g" | E38: Infraestrutura | F38: Obrigatório | G38: todas | I38: criação; manutenção; utilização | K38: alojamentos dimensionados de acordo com as especificidades dos animais
A39: R59-038 | B39: Cães e gatos | C39: RN 59/2023 | D39: art. 2º, I, "h" | E39: Infraestrutura | F39: Obrigatório | G39: todas | I39: criação; manutenção; utilização | K39: área para eutanásia separada do alojamento dos animais
A40: R59-039 | B40: Cães e gatos | C40: RN 59/2023 | D40: art. 2º, I, "i" | E40: Infraestrutura | F40: Obrigatório | G40: todas | I40: criação; manutenção; utilização | K40: área exclusiva para depósitos de resíduos
...

Sheet Contagem
A1: Táxon | B1: RN | C1: Obrigatórios | D1: Recomendados | E1: Total | F1: Itens com restrição de finalidade | G1: Itens com restrição de subgrupo | H1: Divergências registradas | I1: Itens com condição explícita
A2: Roedores e lagomorfos | B2: RN 57/2022 | C2: =COUNTIFS(Criterios!$B$2:$B$286,A2,Criterios!$F$2:$F$286,"Obrigatório") -> 24 | D2: =COUNTIFS(Criterios!$B$2:$B$286,A2,Criterios!$F$2:$F$286,"Recomendado") -> 6 | E2: =COUNTIF(Criterios!$B$2:$B$286,A2) -> 30 | F2: =COUNTIFS(Criterios!$B$2:$B$286,A2)-COUNTIFS(Criterios!$B$2:$B$286,A2,Criterios!$G$2:$G$286,"todas") -> 8 | G2: =COUNTIFS(Criterios!$B$2:$B$286,A2,Criterios!$H$2:$H$286,"<>") -> 0 | H2: =COUNTIFS(Criterios!$B$2:$B$286,A2,Criterios!$L$2:$L$286,"<>") -> 0 | I2: =COUNTIFS(Criterios!$B$2:$B$286,A2,Criterios!$J$2:$J$286,"<>") -> 4
A3: Cães e gatos | B3: RN 59/2023 | C3: =COUNTIFS(Criterios!$B$2:$B$286,A3,Criterios!$F$2:$F$286,"Obrigatório") -> 24 | D3: =COUNTIFS(Criterios!$B$2:$B$286,A3,Criterios!$F$2:$F$286,"Recomendado") -> 13 | E3: =COUNTIF(Criterios!$B$2:$B$286,A3) -> 37 | F3: =COUNTIFS(Criterios!$B$2:$B$286,A3)-COUNTIFS(Criterios!$B$2:$B$286,A3,Criterios!$G$2:$G$286,"todas") -> 5 | G3: =COUNTIFS(Criterios!$B$2:$B$286,A3,Criterios!$H$2:$H$286,"<>") -> 6 | H3: =COUNTIFS(Criterios!$B$2:$B$286,A3,Criterios!$L$2:$L$286,"<>") -> 1 | I3: =COUNTIFS(Criterios!$B$2:$B$286,A3,Criterios!$J$2:$J$286,"<>") -> 3
A4: Primatas não humanos | B4: RN 60/2023 | C4: =COUNTIFS(Criterios!$B$2:$B$286,A4,Criterios!$F$2:$F$286,"Obrigatório") -> 31 | D4: =COUNTIFS(Criterios!$B$2:$B$286,A4,Criterios!$F$2:$F$286,"Recomendado") -> 5 | E4: =COUNTIF(Criterios!$B$2:$B$286,A4) -> 36 | F4: =COUNTIFS(Criterios!$B$2:$B$286,A4)-COUNTIFS(Criterios!$B$2:$B$286,A4,Criterios!$G$2:$G$286,"todas") -> 1 | G4: =COUNTIFS(Criterios!$B$2:$B$286,A4,Criterios!$H$2:$H$286,"<>") -> 0 | H4: =COUNTIFS(Criterios!$B$2:$B$286,A4,Criterios!$L$2:$L$286,"<>") -> 1 | I4: =COUNTIFS(Criterios!$B$2:$B$286,A4,Criterios!$J$2:$J$286,"<>") -> 2
A5: Peixes | B5: RN 61/2023 | C5: =COUNTIFS(Criterios!$B$2:$B$286,A5,Criterios!$F$2:$F$286,"Obrigatório") -> 19 | D5: =COUNTIFS(Criterios!$B$2:$B$286,A5,Criterios!$F$2:$F$286,"Recomendado") -> 10 | E5: =COUNTIF(Criterios!$B$2:$B$286,A5) -> 29 | F5: =COUNTIFS(Criterios!$B$2:$B$286,A5)-COUNTIFS(Criterios!$B$2:$B$286,A5,Criterios!$G$2:$G$286,"todas") -> 0 | G5: =COUNTIFS(Criterios!$B$2:$B$286,A5,Criterios!$H$2:$H$286,"<>") -> 5 | H5: =COUNTIFS(Criterios!$B$2:$B$286,A5,Criterios!$L$2:$L$286,"<>") -> 4 | I5: =COUNTIFS(Criterios!$B$2:$B$286,A5,Criterios!$J$2:$J$286,"<>") -> 0
A6: Anfíbios | B6: RN 62/2023 | C6: =COUNTIFS(Criterios!$B$2:$B$286,A6,Criterios!$F$2:$F$286,"Obrigatório") -> 3 | D6: =COUNTIFS(Criterios!$B$2:$B$286,A6,Criterios!$F$2:$F$286,"Recomendado") -> 3 | E6: =COUNTIF(Criterios!$B$2:$B$286,A6) -> 6 | F6: =COUNTIFS(Criterios!$B$2:$B$286,A6)-COUNTIFS(Criterios!$B$2:$B$286,A6,Criterios!$G$2:$G$286,"todas") -> 0 | G6: =COUNTIFS(Criterios!$B$2:$B$286,A6,Criterios!$H$2:$H$286,"<>") -> 0 | H6: =COUNTIFS(Criterios!$B$2:$B$286,A6,Criterios!$L$2:$L$286,"<>") -> 1 | I6: =COUNTIFS(Criterios!$B$2:$B$286,A6,Criterios!$J$2:$J$286,"<>") -> 0
A7: Serpentes | B7: RN 62/2023 | C7: =COUNTIFS(Criterios!$B$2:$B$286,A7,Criterios!$F$2:$F$286,"Obrigatório") -> 11 | D7: =COUNTIFS(Criterios!$B$2:$B$286,A7,Criterios!$F$2:$F$286,"Recomendado") -> 7 | E7: =COUNTIF(Criterios!$B$2:$B$286,A7) -> 18 | F7: =COUNTIFS(Criterios!$B$2:$B$286,A7)-COUNTIFS(Criterios!$B$2:$B$286,A7,Criterios!$G$2:$G$286,"todas") -> 0 | G7: =COUNTIFS(Criterios!$B$2:$B$286,A7,Criterios!$H$2:$H$286,"<>") -> 0 | H7: =COUNTIFS(Criterios!$B$2:$B$286,A7,Criterios!$L$2:$L$286,"<>") -> 0 | I7: =COUNTIFS(Criterios!$B$2:$B$286,A7,Criterios!$J$2:$J$286,"<>") -> 2
A8: Pequenos ruminantes | B8: RN 63/2023 | C8: =COUNTIFS(Criterios!$B$2:$B$286,A8,Criterios!$F$2:$F$286,"Obrigatório") -> 16 | D8: =COUNTIFS(Criterios!$B$2:$B$286,A8,Criterios!$F$2:$F$286,"Recomendado") -> 15 | E8: =COUNTIF(Criterios!$B$2:$B$286,A8) -> 31 | F8: =COUNTIFS(Criterios!$B$2:$B$286,A8)-COUNTIFS(Criterios!$B$2:$B$286,A8,Criterios!$G$2:$G$286,"todas") -> 0 | G8: =COUNTIFS(Criterios!$B$2:$B$286,A8,Criterios!$H$2:$H$286,"<>") -> 0 | H8: =COUNTIFS(Criterios!$B$2:$B$286,A8,Criterios!$L$2:$L$286,"<>") -> 2 | I8: =COUNTIFS(Criterios!$B$2:$B$286,A8,Criterios!$J$2:$J$286,"<>") -> 4
A9: Grandes ruminantes (bovinos e bubalinos) | B9: RN 64/2023 | C9: =COUNTIFS(Criterios!$B$2:$B$286,A9,Criterios!$F$2:$F$286,"Obrigatório") -> 23 | D9: =COUNTIFS(Criterios!$B$2:$B$286,A9,Criterios!$F$2:$F$286,"Recomendado") -> 20 | E9: =COUNTIF(Criterios!$B$2:$B$286,A9) -> 43 | F9: =COUNTIFS(Criterios!$B$2:$B$286,A9)-COUNTIFS(Criterios!$B$2:$B$286,A9,Criterios!$G$2:$G$286,"todas") -> 2 | G9: =COUNTIFS(Criterios!$B$2:$B$286,A9,Criterios!$H$2:$H$286,"<>") -> 0 | H9: =COUNTIFS(Criterios!$B$2:$B$286,A9,Criterios!$L$2:$L$286,"<>") -> 1 | I9: =COUNTIFS(Criterios!$B$2:$B$286,A9,Criterios!$J$2:$J$286,"<>") -> 5
A10: Equídeos | B10: RN 65/2023 | C10: =COUNTIFS(Criterios!$B$2:$B$286,A10,Criterios!$F$2:$F$286,"Obrigatório") -> 13 | D10: =COUNTIFS(Criterios!$B$2:$B$286,A10,Criterios!$F$2:$F$286,"Recomendado") -> 9 | E10: =COUNTIF(Criterios!$B$2:$B$286,A10) -> 22 | F10: =COUNTIFS(Criterios!$B$2:$B$286,A10)-COUNTIFS(Criterios!$B$2:$B$286,A10,Criterios!$G$2:$G$286,"todas") -> 1 | G10: =COUNTIFS(Criterios!$B$2:$B$286,A10,Criterios!$H$2:$H$286,"<>") -> 0 | H10: =COUNTIFS(Criterios!$B$2:$B$286,A10,Criterios!$L$2:$L$286,"<>") -> 0 | I10: =COUNTIFS(Criterios!$B$2:$B$286,A10,Criterios!$J$2:$J$286,"<>") -> 1
A11: Suínos | B11: RN 66/2023 | C11: =COUNTIFS(Criterios!$B$2:$B$286,A11,Criterios!$F$2:$F$286,"Obrigatório") -> 16 | D11: =COUNTIFS(Criterios!$B$2:$B$286,A11,Criterios!$F$2:$F$286,"Recomendado") -> 2 | E11: =COUNTIF(Criterios!$B$2:$B$286,A11) -> 18 | F11: =COUNTIFS(Criterios!$B$2:$B$286,A11)-COUNTIFS(Criterios!$B$2:$B$286,A11,Criterios!$G$2:$G$286,"todas") -> 2 | G11: =COUNTIFS(Criterios!$B$2:$B$286,A11,Criterios!$H$2:$H$286,"<>") -> 0 | H11: =COUNTIFS(Criterios!$B$2:$B$286,A11,Criterios!$L$2:$L$286,"<>") -> 0 | I11: =COUNTIFS(Criterios!$B$2:$B$286,A11,Criterios!$J$2:$J$286,"<>") -> 3
A12: Aves | B12: RN 67/2023 | C12: =COUNTIFS(Criterios!$B$2:$B$286,A12,Criterios!$F$2:$F$286,"Obrigatório") -> 13 | D12: =COUNTIFS(Criterios!$B$2:$B$286,A12,Criterios!$F$2:$F$286,"Recomendado") -> 2 | E12: =COUNTIF(Criterios!$B$2:$B$286,A12) -> 15 | F12: =COUNTIFS(Criterios!$B$2:$B$286,A12)-COUNTIFS(Criterios!$B$2:$B$286,A12,Criterios!$G$2:$G$286,"todas") -> 0 | G12: =COUNTIFS(Criterios!$B$2:$B$286,A12,Criterios!$H$2:$H$286,"<>") -> 0 | H12: =COUNTIFS(Criterios!$B$2:$B$286,A12,Criterios!$L$2:$L$286,"<>") -> 0 | I12: =COUNTIFS(Criterios!$B$2:$B$286,A12,Criterios!$J$2:$J$286,"<>") -> 1
A13: TOTAL | C13: =SUM(C2:C12) -> 193 | D13: =SUM(D2:D12) -> 92 | E13: =SUM(E2:E12) -> 285 | F13: =SUM(F2:F12) -> 19 | G13: =SUM(G2:G12) -> 11 | H13: =SUM(H2:H12) -> 10 | I13: =SUM(I2:I12) -> 25

Sheet Como usar
A1: Planilha-fonte dos critérios de licenciamento — CEUA UFPR Palotina
A3: Origem: textos das Resoluções Normativas publicados no DOU, transcritos alínea por alínea.
A4: Data da extração: 31/08/2026.
A6: REGRAS DE TRANSCRIÇÃO
A7: 1. Uma linha por alínea. A chave é o dispositivo. Item sem dispositivo não entra.
A8: 2. Obrigatório = art. 2º (art. 4º na RN 62, para serpentes). Recomendado = art. 3º (art. 5º na RN 62).
A9: 3. O Anexo de cada RN NÃO é fonte de classificação. Serve só de conferência; onde diverge do
A10: artigo, a divergência fica registrada na coluna Nota e prevalece o artigo.
A11: 4. A coluna Finalidade só é preenchida quando a própria alínea traz a restrição por escrito
A12: ('em biotérios de criação', 'em instalação de criação'). Sem essa expressão, o valor é 'todas'.
A14: COMO AUDITAR UM FORMULÁRIO
A15: Cruzar a lista de itens do formulário com a coluna Dispositivo. Item do formulário sem
... A39: expressa, e não depende de interpretação da CEUA.

Sheet Conflitos RN-Anexo
A1: RN | B1: Táxon | C1: Dispositivo | D1: Ponto | E1: O que diz o artigo | F1: O que diz o Anexo | G1: Regra adotada
A2: RN 59/2023 | B2: Cães e gatos | C2: art. 2º, I, "f" | D2: Sanitários | E2: sanitários separados das áreas controladas ou de criação — sem restrição de finalidade | F2: restringe: sanitários fora de áreas controladas em instalações de criação | G2: Prevalece o artigo. Item exigível em qualquer finalidade.
A3: RN 61/2023 | B3: Peixes | C3: art. 2º, I, "l" | D3: Parâmetros da água | E3: filtragem, pH, oxigênio dissolvido, salinidade e níveis de amônia e nitrito | F3: Anexo I traz 'controle de amônia e dureza da água' — não menciona salinidade | G3: Prevalece o artigo. Salinidade é exigível; dureza não é requisito normativo.
A4: RN 61/2023 | B4: Peixes | C4: art. 2º, I, "e" | D4: Barreiras sanitárias | E4: barreiras de bioexclusão e biocontenção conforme o nível de biossegurança | F4: ausente do Anexo II | G4: Prevalece o artigo. Exigível também para os peixes do Anexo II.
A5: RN 61/2023 | B5: Peixes | C5: art. 2º, II, "c" | D5: Controle de patógenos | E5: controle de patógenos nos aquários de peixes de laboratório | F5: ausente do Anexo II | G5: Prevalece o artigo, com a restrição de subgrupo que ele próprio traz.
A6: RN 61/2023 | B6: Peixes | C6: art. 2º, II, "g" | D6: EPI | E6: equipamentos de proteção individual conforme o nível de biossegurança | F6: ausente do Anexo II | G6: Prevalece o artigo. Exigível também para os peixes do Anexo II.
A7: RN 61/2023 | B7: Peixes | C7: art. 1º e Anexos I e II | D7: Divisão em dois grupos | E7: o art. 2º vale para todos os peixes; só alguns itens dizem 'para peixes de laboratório' | F7: os Anexos I e II separam peixes de laboratório dos demais | G7: A divisão é dos Anexos, não da norma. Não tratar como dois táxons distintos.
A8: RN 62/2023 | B8: Anfíbios | C8: art. 3º, I | D8: Registro da alimentação | E8: art. 3º, I — item recomendado | F8: Anexo classifica como Obrigatório | G8: Prevalece o artigo: Recomendado.
A9: RN 63/2023 | B9: Pequenos ruminantes | C9: art. 3º, XII e XII (bis) | D9: Numeração | E9: dois incisos diferentes recebem o número XII | F9: — | G9: Erro de numeração na fonte. Mantidos ambos, o segundo identificado como XII (bis).
A10: RN 64/2023 | B10: Grandes ruminantes | C10: art. 2º, I, "p" | D10: Área cirúrgica | E10: art. 2º, I, 'p' — item obrigatório | F10: o Anexo lista o mesmo item duas vezes: uma como Recomendado, outra como Obrigatório | G10: Prevalece o artigo: Obrigatório, ocorrência única.

Sheet Normas transversais
A1: Norma | B1: Tema | C1: O que rege | D1: Uso nesta matriz e nos formulários
A2: Lei 11.794/2008 | B2: Lei Arouca | C2: Cria o CONCEA e as CEUAs; define o regime do uso de animais em ensino e pesquisa científica. | D2: Fundamento de todo o resto. O termo 'laboratório de experimentação' vem dela e permanece sem regulamentação complementar.
A3: Lei 15.183/2025 | B3: Testes de cosméticos | C3: Veda o uso de animais vertebrados vivos em testes de produtos de higiene pessoal, cosméticos e perfumes e de seus ingredientes; acrescenta os §§ 11 a 18 ao art. 14 da Lei 11.794. | D3: Matéria de análise de protocolo pela CEUA. Não afeta enquadramento nem licenciamento de instalação.
A4: RN 30/2016, atualizada pela RN 55/2022 | B4: DBCA | C4: Diretriz Brasileira para o Cuidado e a Utilização de Animais em Atividades de Ensino ou Pesquisa Científica. | D4: Fonte subsidiária. Não classifica itens como obrigatório ou recomendado por táxon — isso é das RNs específicas.
A5: RN 51/2021, alterada pela RN 73/2025 | B5: CEUAs e instalações | C5: Funcionamento das CEUAs, vínculo das instalações, coordenação e Responsável Técnico. | D5: Base dos campos gerais dos formulários (coordenador, RT, vínculo). A RN 73/2025 revogou as alíneas 'a' e 'b' do art. 14, II.
A6: RN 22/2015 | B6: Animais domésticos fora de instalações | C6: Estudos conduzidos com animais domésticos mantidos fora de instalações de instituições de ensino ou pesquisa. Traz, no item 3.13, a definição oficial de instalação animal. | D6: Define a fronteira do que é instalação animal. Não gera itens de checklist.
A7: Portaria MCTI 9.037/2025, alterada pela 9.299/2025 | B7: Licenciamento no CIUCA | C7: Institui o licenciamento das instalações animais. Art. 3º: exige o atendimento, no mínimo, dos critérios de caráter obrigatório. Art. 4º, V e §1º: licença por táxon em cada instalação. | D7: É a régua desta matriz. Só a coluna Classificação = Obrigatório bloqueia o licenciamento.
A8: Nota Informativa CONCEA de 29/04/2026 | B8: Instalações médico-veterinárias e unidades de produção | C8: Define consultórios, ambulatórios, clínicas e hospitais veterinários e estruturas de produção agropecuária; exige licenciamento quando há ensino ou pesquisa. | D8: Autoriza assinalar 'não se aplica' com justificativa no checklist dessas instalações. Não menciona centros de triagem.
A9: Nota Informativa CONCEA de 09/07/2026 | B9: Laboratórios de experimentação | C9: Sala de procedimentos separada de instalação licenciada, exclusiva para roedores, duração menor que 12 horas e sem possibilidade de alojamento. | D9: Não gera checklist próprio. Registro no item 2.1.1 do cadastro de instalações do CIUCA.
